<?xml version="1.0"?>
<!-- vim: set ft=xml sw=2 : -->
<robot name="Stomp">
  <link name="base">
    <visual>
      <geometry>
        <box size="0.3 0.3 0.02"/>
      </geometry>
      <origin xyz="0 0 -0.01"/>
    </visual>
  </link>
  <joint name="pivot" type="continuous">
    <parent link="base"/>
    <child link="hip"/>
    <axis xyz="0 0 1"/>
    <origin xyz="0.0 -0.11 0.11" rpy="0 0 0"/>
  </joint>
  <link name="hip">
    <visual>
      <geometry>
        <mesh filename="Leg 1 Hip Simplified.obj"/>
      </geometry>
    </visual>
    <inertial>
      <origin xyz="-0.002 -0.004 -0.025"/>
      <mass value="2.067"/>
      <inertia ixx="0.009" ixy="0" ixz="0" iyy="0.011" iyz="-0.001" izz="0.007"/>
    </inertial>
    <collision>
    </collision>
  </link>
  <!--
  <joint name="pivot_cylinder_base" type="continuous">
    <parent link="base"/>
    <child link="pivot_cylinder"/>
    <origin xyz="-0.06543 0.0915 0.135" rpy="0 1.57 0"/>
    <axis xyz="0 0 1"/>
  </joint>
  <link name="pivot_cylinder">
    <visual>
      <geometry>
        <cylinder length="0.10" radius="0.027"/>
      </geometry>
      <origin xyz="0 0 -0.05"/>
    </visual>
  </link>
  <joint name="pivot_cylinder_slide" type="prismatic">
    <parent link="pivot_cylinder"/>
    <child link="pivot_rod"/>
    <axis xyz="0 0 1"/>
  </joint>
  <link name="pivot_rod">
    <visual>
      <geometry>
        <cylinder length="0.10" radius="0.01"/>
      </geometry>
    </visual>
  </link>
  <joint name="pivot_yoke" type="continuous">
    <parent link="pivot_rod"/>
    <child link="hip"/>
    <origin xyz="0 0.099 0"/>
  </joint>
  -->
  <joint name="knee" type="continuous">
    <parent link="hip" />
    <child link="thigh" />
    <origin xyz="0 -0.041 0.0" />
    <axis xyz="1 0 0" />
  </joint>
  <link name="thigh">
    <visual>
      <geometry>
        <mesh filename="Leg 1 Thigh Simplified.obj"/>
      </geometry>
    </visual>
    <inertial>
      <origin xyz="0 -0.048 -0.003"/>
      <mass value="1.512"/>
      <inertia ixx="0.01" ixy="0" ixz="0" iyy="0.002" iyz="0" izz="0.011"/>
    </inertial>
    <collision>
    </collision>
  </link>
  <joint name="ankle" type="continuous">
    <parent link="thigh" />
    <child link="foot" />
    <origin xyz="0 -0.160 0" />
    <axis xyz="1 0 0" />
  </joint>
  <link name="foot">
    <visual>
      <geometry>
        <mesh filename="Leg 1 Foot Simplified.obj"/>
      </geometry>
    </visual>
    <inertial>
      <origin xyz="0 -0.008 -0.053"/>
      <mass value="0.600"/>
      <inertia ixx=".003" ixy="0" ixz="0" iyy="0.002" iyz="0" izz="0.0003"/>
    </inertial>
  </link>
</robot>
